import { render, screen } from '@testing-library/react';
import { vi } from 'vitest';
import { ErrorBoundary } from './ErrorBoundary';

function ThrowError({ shouldThrow }: { shouldThrow: boolean }) {
  if (shouldThrow) {
    throw new Error('Test error');
  }
  return <div>No error</div>;
}

describe('ErrorBoundary', () => {
  const originalError = console.error;
  
  beforeEach(() => {
    console.error = vi.fn();
  });

  afterEach(() => {
    console.error = originalError;
  });

  it('renders children when there is no error', () => {
    render(
      <ErrorBoundary>
        <ThrowError shouldThrow={false} />
      </ErrorBoundary>
    );

    expect(screen.getByText('No error')).toBeInTheDocument();
  });

  it('renders error message when child throws error', () => {
    render(
      <ErrorBoundary>
        <ThrowError shouldThrow={true} />
      </ErrorBoundary>
    );

    expect(screen.getByText(/Something went wrong/)).toBeInTheDocument();
    expect(screen.getByText('Refresh Page')).toBeInTheDocument();
  });

  it('renders custom fallback when provided', () => {
    const customFallback = <div>Custom error fallback</div>;
    
    render(
      <ErrorBoundary fallback={customFallback}>
        <ThrowError shouldThrow={true} />
      </ErrorBoundary>
    );

    expect(screen.getByText('Custom error fallback')).toBeInTheDocument();
    expect(screen.queryByText(/Something went wrong/)).not.toBeInTheDocument();
  });

  it('logs error to console', () => {
    render(
      <ErrorBoundary>
        <ThrowError shouldThrow={true} />
      </ErrorBoundary>
    );

    expect(console.error).toHaveBeenCalled();
  });
});